<?xml version = "1.0" ?>
<robot name = "bturtle" xmlns:xacro ="http://ros.org/wiki/xacro" >
    <link name="world"/>

    <joint name="world_to_base" type="fixed">
        <origin rpy="0 0 0" xyz="0 0 0"/>
        <parent link="world"/>
        <child link="base_footprint"/>
    </joint>

	<xacro:macro name = "Chassis_origin">
		<origin xyz = "0 0 0" rpy = "0 0 0"/>
	</xacro:macro>
	<xacro:macro name = "Right_Wheel_Origin">
		<origin rpy = "1.5708 0 0" xyz = "0 0.0150 0"/> <!-- Previous <origin rpy = "0 0 0" xyz = "-0.0135 0.0150 -0.0785"/> -->
	</xacro:macro>
	<xacro:macro name ="Left_Wheel_Origin">

		<origin rpy = "1.5708 0 0" xyz = "0 -0.015 0"/> <!-- <origin rpy = "0 0 0" xyz = "-0.016 -0.015 -0.0785"/> -->

	</xacro:macro> 
	<xacro:macro name = "Chassis1" >
			<geometry>
				<box size = "0.075 0.175 0.157" /> <!-- 0.075 0.175 0.157 -->
				 
			</geometry>
	</xacro:macro>
	<xacro:macro name = "cylinder1" >
		<geometry>
			<cylinder radius="0.0316" length ="0.037"/>
			
		</geometry>
	</xacro:macro> 
	<xacro:macro name = "Chassis_Mesh" >
		<geometry>
				<!--<box size = "0.075 0.175 0.157"/> -->
				<mesh filename = "package://bturtle_description/meshes/Assem_No_wheel.dae" scale = "0.001 0.001 0.001" />
				<!--<mesh filename ="package://bturtle_description/meshes/Assem2_No_Wheel.STL"/>-->
		</geometry>
		<origin xyz ="-0.05 -0.090 -.157" rpy = "0 0 0" />
	</xacro:macro>


	<xacro:macro name = "Right_Wheel_Mesh" >
		<geometry>
			<mesh filename="package://bturtle_description/meshes/WheelZTinyRight.dae"/>
		</geometry>
		<origin rpy = "0 0 0" xyz = "0 0.0150 -0.0785"/>

	</xacro:macro>

	<xacro:macro name = "Left_Wheel_Mesh" >
		<geometry>
				<mesh filename="package://bturtle_description/meshes/WheelZTinyRight.dae"/>
		</geometry>
	</xacro:macro>

	<xacro:macro name = "Wheel_Inertia">
		<inertia ixx ="0.000096758" ixz = "0.0" iyy = "0.000068429" iyz = "0.0000" ixy = "0.0" izz = "0.000096758"/>
	</xacro:macro> 

	<sdf version = "1.4"/>
	<link name="base_footprint">
		<visual>
			<origin xyz="0 0 0" rpy="0 0 0" />
			<geometry>
				<box size="0.001 0.001 0.001" />
			</geometry>
		</visual>
	</link>
	<joint name="base_link_joint" type="fixed">
		<origin xyz = "0 0 0.001" rpy = "0 0 0" />
		<parent link="base_footprint"/>
		<child link="Chassis" />
	</joint> 


	

<link name = "Chassis">
		<inertial>
			<origin xyz = "0.0375 0 0" rpy = "0 0 0" />
			<mass value = "0.388"/>
			<inertia ixx ="0.0113" iyy=".01094" izz=".00971" ixy="0" ixz ="0" iyz = "0"/>
		</inertial>
		<collision>
			<xacro:Chassis1 /><!--
			<origin rpy = "0 0 0" xyz ="0 0 0.1101"/> -->
			<xacro:Chassis_origin /> 
			
		</collision>
		<visual>
			<xacro:Chassis_Mesh />
			
		
			

		</visual>
	</link>

	<link name = "Right_Wheel">
		<inertial>
			<origin xyz = "0.0 0.0185 0" rpy = "0 0 0" />
			<mass value ="0.03770"/>
			<xacro:Wheel_Inertia />
		</inertial>
		<collision>
			<xacro:cylinder1 />
			<xacro:Right_Wheel_Origin />
			<!--
			<origin rpy = "0 0 0" xyz = "0 0.1100 0.0316"/> -->
			

		</collision>
		<visual>
			<xacro:cylinder1 />
			
			<xacro:Right_Wheel_Origin />  
			
		</visual>
	</link>
	<joint name ="Right_wheel_Joint" type = "continuous">
		<parent link = "base_footprint"/>
		<child link = "Right_Wheel"/>
		<origin xyz = "-0.0135 0.0875 -0.0785" rpy ="0 0 0.0"/>
		<limit effort="100000" velocity="100000"/>
        <axis xyz="0 1 0"/>
	</joint>
	<link name = "Left_Wheel">
		<inertial>
			<origin xyz = "0.0 0.0185 0" rpy = "0 0 0" />
			<mass value ="0.03770"/>
			<xacro:Wheel_Inertia />
		</inertial>
		<collision>
			<xacro:cylinder1 />
			<xacro:Left_Wheel_Origin />
		</collision>
		<visual>
			<xacro:cylinder1 />
			
			<xacro:Left_Wheel_Origin /> 
			
		</visual>
	</link>
	<joint name ="Left_wheel_Joint" type = "continuous">
		<parent link = "base_footprint"/>
		<child link = "Left_Wheel"/>
		<origin xyz = "-0.016 -0.0875 -0.0785" rpy ="0 0 0.0"/>
		<limit effort="100000" velocity="100000"/>
        <axis xyz="0 1 0"/>
	</joint>


    <ros2_control name="GazeboSystem" type="system">
      <hardware>
        <plugin>gazebo_ros2_control/GazeboSystem</plugin>
      </hardware>
      <joint name="Right_wheel_Joint">
        <command_interface name="velocity"/>
        <state_interface name="position"/>
        <state_interface name="velocity"/>
        <state_interface name="effort"/>
      </joint>
      <joint name="Left_wheel_Joint">
        <command_interface name="velocity"/>
        <state_interface name="position"/>
        <state_interface name="velocity"/>
        <state_interface name="effort"/>
      </joint>
    </ros2_control>

    <gazebo>
        <plugin filename="libgazebo_ros2_control.so" name="gazebo_ros2_control">
        <robot_sim_type>gazebo_ros2_control/GazeboSystem</robot_sim_type>
        <parameters>$(find bturtle_description)/config/controllers.yaml</parameters>
        </plugin>
    </gazebo>



</robot>
